Workbook

Sheet Daily_table
A1: Date | B1: Name | C1: Age | D1: Gender | E1: Refer By | F1: Test | G1: Price | H1: Refer Fee % | I1: Refer Fee Amount | K1: Total= | L1: =SUM(Daily_table!$G$2:$G$196) -> 3690000
A2: 46082 | B2: Daw Win Naw | C2: 43 yrs | D2: F | E2: Self | F2: CP(A) | G2: =IFERROR(VLOOKUP(F2, Price_Master!$A$2:$C$201, 2, FALSE), "") -> 30000 | H2: =IFERROR(VLOOKUP(F2, Price_Master!$A$2:$C$201, 3, FALSE), 0) -> 0.15 | I2: =IFERROR(G2*H2, "") -> 4500
A3: 46083 | B3: Ma Su Mon Kyaw | C3: 30 yrs | D3: F | E3: ဂရုဏာဆေးခန်း | F3: U/A | G3: =IFERROR(VLOOKUP(F3, Price_Master!$A$2:$C$201, 2, FALSE), "") -> 10000 | H3: =IFERROR(VLOOKUP(F3, Price_Master!$A$2:$C$201, 3, FALSE), 0) -> 0.15 | I3: =IFERROR(G3*H3, "") -> 1500
A4: 46083 | B4: U Maung Maung Aye | C4: 36 yrs | D4: M | E4: MCLH | F4: Urine Analysis | G4: =IFERROR(VLOOKUP(F4, Price_Master!$A$2:$C$201, 2, FALSE), "") -> 12000 | H4: =IFERROR(VLOOKUP(F4, Price_Master!$A$2:$C$201, 3, FALSE), 0) -> 0.05 | I4: =IFERROR(G4*H4, "") -> 600
A5: 46083 | E5: MCLH | F5: Creat | G5: =IFERROR(VLOOKUP(F5, Price_Master!$A$2:$C$201, 2, FALSE), "") -> 10000 | H5: =IFERROR(VLOOKUP(F5, Price_Master!$A$2:$C$201, 3, FALSE), 0) -> 0.15 | I5: =IFERROR(G5*H5, "") -> 1500
A6: 46083 | B6: U Boe Win | C6: 65 yrs | D6: M | E6: Phy | F6: CP(A) | G6: =IFERROR(VLOOKUP(F6, Price_Master!$A$2:$C$201, 2, FALSE), "") -> 30000 | H6: =IFERROR(VLOOKUP(F6, Price_Master!$A$2:$C$201, 3, FALSE), 0) -> 0.15 | I6: =IFERROR(G6*H6, "") -> 4500
A7: 46083 | E7: Phy | F7: E Lytes | G7: =IFERROR(VLOOKUP(F7, Price_Master!$A$2:$C$201, 2, FALSE), "") -> 30000 | H7: =IFERROR(VLOOKUP(F7, Price_Master!$A$2:$C$201, 3, FALSE), 0) -> 0.15 | I7: =IFERROR(G7*H7, "") -> 4500
A8: 46083 | E8: Phy | F8: Creat | G8: =IFERROR(VLOOKUP(F8, Price_Master!$A$2:$C$201, 2, FALSE), "") -> 10000 | H8: =IFERROR(VLOOKUP(F8, Price_Master!$A$2:$C$201, 3, FALSE), 0) -> 0.15 | I8: =IFERROR(G8*H8, "") -> 1500
A9: 46083 | E9: Phy | F9: Lipid | G9: =IFERROR(VLOOKUP(F9, Price_Master!$A$2:$C$201, 2, FALSE), "") -> 36000 | H9: =IFERROR(VLOOKUP(F9, Price_Master!$A$2:$C$201, 3, FALSE), 0) -> 0.15 | I9: =IFERROR(G9*H9, "") -> 5400
A10: 46083 | E10: Phy | F10: Trop-T | G10: =IFERROR(VLOOKUP(F10, Price_Master!$A$2:$C$201, 2, FALSE), "") -> 40000 | H10: =IFERROR(VLOOKUP(F10, Price_Master!$A$2:$C$201, 3, FALSE), 0) -> 0 | I10: =IFERROR(G10*H10, "") -> 0
A11: 46083 | E11: Phy | F11: LFT | G11: =IFERROR(VLOOKUP(F11, Price_Master!$A$2:$C$201, 2, FALSE), "") -> 36000 | H11: =IFERROR(VLOOKUP(F11, Price_Master!$A$2:$C$201, 3, FALSE), 0) -> 0.15 | I11: =IFERROR(G11*H11, "") -> 5400
A12: 46083 | B12: U Kyaw Hein | C12: 40 yrs | D12: M | E12: Phy | F12: LFT | G12: =IFERROR(VLOOKUP(F12, Price_Master!$A$2:$C$201, 2, FALSE), "") -> 36000 | H12: =IFERROR(VLOOKUP(F12, Price_Master!$A$2:$C$201, 3, FALSE), 0) -> 0.15 | I12: =IFERROR(G12*H12, "") -> 5400
A13: 46084 | B13: Ma Paing Thein Kha | C13: 27 yrs | D13: F | E13: Self | F13: G&M | G13: =IFERROR(VLOOKUP(F13, Price_Master!$A$2:$C$201, 2, FALSE), "") -> 7000 | H13: =IFERROR(VLOOKUP(F13, Price_Master!$A$2:$C$201, 3, FALSE), 0) -> 0.15 | I13: =IFERROR(G13*H13, "") -> 1050
A14: 46084 | B14: Ko Khant Nyein Aung | C14: 29 yrs | D14: M | E14: Self | F14: G&M | G14: =IFERROR(VLOOKUP(F14, Price_Master!$A$2:$C$201, 2, FALSE), "") -> 7000 | H14: =IFERROR(VLOOKUP(F14, Price_Master!$A$2:$C$201, 3, FALSE), 0) -> 0.15 | I14: =IFERROR(G14*H14, "") -> 1050
A15: 46084 | B15: Ma Paing Shal May | C15: 25 yrs | D15: F | E15: Self | F15: G&M Rh | G15: =IFERROR(VLOOKUP(F15, Price_Master!$A$2:$C$201, 2, FALSE), "") -> 10000 | H15: =IFERROR(VLOOKUP(F15, Price_Master!$A$2:$C$201, 3, FALSE), 0) -> 0.15 | I15: =IFERROR(G15*H15, "") -> 1500
A16: 46084 | B16: Daw Aye Aye Maw | C16: 53 yrs | D16: F | E16: Self | F16: G&M Rh | G16: =IFERROR(VLOOKUP(F16, Price_Master!$A$2:$C$201, 2, FALSE), "") -> 10000 | H16: =IFERROR(VLOOKUP(F16, Price_Master!$A$2:$C$201, 3, FALSE), 0) -> 0.15 | I16: =IFERROR(G16*H16, "") -> 1500
A17: 46084 | B17: Ma Hnin Eain Thu | C17: 20 yrs | D17: F | E17: OG | F17: URE | G17: =IFERROR(VLOOKUP(F17, Price_Master!$A$2:$C$201, 2, FALSE), "") -> 12000 | H17: =IFERROR(VLOOKUP(F17, Price_Master!$A$2:$C$201, 3, FALSE), 0) -> 0.05 | I17: =IFERROR(G17*H17, "") -> 600
A18: 46085 | B18: Daw Yee Win | C18: 54 yrs | D18: F | E18: Phy | F18: E Lytes | G18: =IFERROR(VLOOKUP(F18, Price_Master!$A$2:$C$201, 2, FALSE), "") -> 30000 | H18: =IFERROR(VLOOKUP(F18, Price_Master!$A$2:$C$201, 3, FALSE), 0) -> 0.15 | I18: =IFERROR(G18*H18, "") -> 4500
A19: 46085 | E19: Phy | F19: Lipid | G19: =IFERROR(VLOOKUP(F19, Price_Master!$A$2:$C$201, 2, FALSE), "") -> 36000 | H19: =IFERROR(VLOOKUP(F19, Price_Master!$A$2:$C$201, 3, FALSE), 0) -> 0.15 | I19: =IFERROR(G19*H19, "") -> 5400
A20: 46085 | B20: Mg Zwe Bhone Pyae Mg | C20: 10/12 yrs | D20: M | E20: NMMN | F20: CP(A) | G20: =IFERROR(VLOOKUP(F20, Price_Master!$A$2:$C$201, 2, FALSE), "") -> 30000 | H20: =IFERROR(VLOOKUP(F20, Price_Master!$A$2:$C$201, 3, FALSE), 0) -> 0.15 | I20: =IFERROR(G20*H20, "") -> 4500
A21: 46085 | E21: NMMN | F21: CRP | G21: =IFERROR(VLOOKUP(F21, Price_Master!$A$2:$C$201, 2, FALSE), "") -> 25000 | H21: =IFERROR(VLOOKUP(F21, Price_Master!$A$2:$C$201, 3, FALSE), 0) -> 0.05 | I21: =IFERROR(G21*H21, "") -> 1250
A22: 46086 | B22: Ma Hsut Hsai Hsan | C22: 13 yrs | D22: F | E22: Self | F22: G&M | G22: =IFERROR(VLOOKUP(F22, Price_Master!$A$2:$C$201, 2, FALSE), "") -> 7000 | H22: =IFERROR(VLOOKUP(F22, Price_Master!$A$2:$C$201, 3, FALSE), 0) -> 0.15 | I22: =IFERROR(G22*H22, "") -> 1050
A23: 46087 | B23: U Thein Win | C23: 47 yrs | D23: M | E23: Phy | F23: Lipid | G23: =IFERROR(VLOOKUP(F23, Price_Master!$A$2:$C$201, 2, FALSE), "") -> 36000 | H23: =IFERROR(VLOOKUP(F23, Price_Master!$A$2:$C$201, 3, FALSE), 0) -> 0.15 | I23: =IFERROR(G23*H23, "") -> 5400
A24: 46088 | B24: Daw Kham | C24: 46 yrs | D24: F | E24: MCLH | F24: Urine Analysis | G24: =IFERROR(VLOOKUP(F24, Price_Master!$A$2:$C$201, 2, FALSE), "") -> 12000 | H24: =IFERROR(VLOOKUP(F24, Price_Master!$A$2:$C$201, 3, FALSE), 0) -> 0.05 | I24: =IFERROR(G24*H24, "") -> 600
A25: 46088 | E25: MCLH | F25: HbA1C | G25: =IFERROR(VLOOKUP(F25, Price_Master!$A$2:$C$201, 2, FALSE), "") -> 25000 | H25: =IFERROR(VLOOKUP(F25, Price_Master!$A$2:$C$201, 3, FALSE), 0) -> 0.05 | I25: =IFERROR(G25*H25, "") -> 1250
A26: 46088 | E26: MCLH | F26: Creat | G26: =IFERROR(VLOOKUP(F26, Price_Master!$A$2:$C$201, 2, FALSE), "") -> 10000 | H26: =IFERROR(VLOOKUP(F26, Price_Master!$A$2:$C$201, 3, FALSE), 0) -> 0.15 | I26: =IFERROR(G26*H26, "") -> 1500
A27: 46088 | E27: MCLH | F27: LFT | G27: =IFERROR(VLOOKUP(F27, Price_Master!$A$2:$C$201, 2, FALSE), "") -> 36000 | H27: =IFERROR(VLOOKUP(F27, Price_Master!$A$2:$C$201, 3, FALSE), 0) -> 0.15 | I27: =IFERROR(G27*H27, "") -> 5400
A28: 46088 | E28: MCLH | F28: Lipid | G28: =IFERROR(VLOOKUP(F28, Price_Master!$A$2:$C$201, 2, FALSE), "") -> 36000 | H28: =IFERROR(VLOOKUP(F28, Price_Master!$A$2:$C$201, 3, FALSE), 0) -> 0.15 | I28: =IFERROR(G28*H28, "") -> 5400
A29: 46089 | B29: U Myo Latt Aung | C29: 35 yrs | D29: M | E29: Phy | F29: CP(A) | G29: =IFERROR(VLOOKUP(F29, Price_Master!$A$2:$C$201, 2, FALSE), "") -> 30000 | H29: =IFERROR(VLOOKUP(F29, Price_Master!$A$2:$C$201, 3, FALSE), 0) -> 0.15 | I29: =IFERROR(G29*H29, "") -> 4500
A30: 46089 | E30: Phy | F30: ASO (Quanti) | G30: =IFERROR(VLOOKUP(F30, Price_Master!$A$2:$C$201, 2, FALSE), "") -> 30000 | H30: =IFERROR(VLOOKUP(F30, Price_Master!$A$2:$C$201, 3, FALSE), 0) -> 0.05 | I30: =IFERROR(G30*H30, "") -> 1500
A31: 46089 | E31: Phy | F31: MP (ICT) | G31: =IFERROR(VLOOKUP(F31, Price_Master!$A$2:$C$201, 2, FALSE), "") -> 10000 | H31: =IFERROR(VLOOKUP(F31, Price_Master!$A$2:$C$201, 3, FALSE), 0) -> 0.05 | I31: =IFERROR(G31*H31, "") -> 500
A32: 46089 | E32: Phy | F32: Dengue Duo | G32: =IFERROR(VLOOKUP(F32, Price_Master!$A$2:$C$201, 2, FALSE), "") -> 25000 | H32: =IFERROR(VLOOKUP(F32, Price_Master!$A$2:$C$201, 3, FALSE), 0) -> 0.05 | I32: =IFERROR(G32*H32, "") -> 1250
A33: 46089 | B33: Daw Cho Sann | C33: 53 yrs | D33: F | E33: Phy | F33: CP(A) | G33: =IFERROR(VLOOKUP(F33, Price_Master!$A$2:$C$201, 2, FALSE), "") -> 30000 | H33: =IFERROR(VLOOKUP(F33, Price_Master!$A$2:$C$201, 3, FALSE), 0) -> 0.15 | I33: =IFERROR(G33*H33, "") -> 4500
A34: 46089 | E34: Phy | F34: URE | G34: =IFERROR(VLOOKUP(F34, Price_Master!$A$2:$C$201, 2, FALSE), "") -> 12000 | H34: =IFERROR(VLOOKUP(F34, Price_Master!$A$2:$C$201, 3, FALSE), 0) -> 0.05 | I34: =IFERROR(G34*H34, "") -> 600
A35: 46089 | E35: Phy | F35: HbA1C | G35: =IFERROR(VLOOKUP(F35, Price_Master!$A$2:$C$201, 2, FALSE), "") -> 25000 | H35: =IFERROR(VLOOKUP(F35, Price_Master!$A$2:$C$201, 3, FALSE), 0) -> 0.05 | I35: =IFERROR(G35*H35, "") -> 1250
A36: 46089 | E36: Phy | F36: E Lytes | G36: =IFERROR(VLOOKUP(F36, Price_Master!$A$2:$C$201, 2, FALSE), "") -> 30000 | H36: =IFERROR(VLOOKUP(F36, Price_Master!$A$2:$C$201, 3, FALSE), 0) -> 0.15 | I36: =IFERROR(G36*H36, "") -> 4500
A37: 46089 | E37: Phy | F37: Creat | G37: =IFERROR(VLOOKUP(F37, Price_Master!$A$2:$C$201, 2, FALSE), "") -> 10000 | H37: =IFERROR(VLOOKUP(F37, Price_Master!$A$2:$C$201, 3, FALSE), 0) -> 0.15 | I37: =IFERROR(G37*H37, "") -> 1500
A38: 46089 | E38: Phy | F38: Lipid | G38: =IFERROR(VLOOKUP(F38, Price_Master!$A$2:$C$201, 2, FALSE), "") -> 36000 | H38: =IFERROR(VLOOKUP(F38, Price_Master!$A$2:$C$201, 3, FALSE), 0) -> 0.15 | I38: =IFERROR(G38*H38, "") -> 5400
A39: 46089 | B39: Mg Toe Ni | C39: 21 yrs | D39: M | E39: ဂရုဏာဆေးခန်း | F39: VDRL | G39: =IFERROR(VLOOKUP(F39, Price_Master!$A$2:$C$201, 2, FALSE), "") -> 7000 | H39: =IFERROR(VLOOKUP(F39, Price_Master!$A$2:$C$201, 3, FALSE), 0) -> 0.05 | I39: =IFERROR(G39*H39, "") -> 350
A40: 46089 | B40: U Aung Tin Win | C40: 48 yrs | D40: M | E40: MCLH | F40: Urine Analysis | G40: =IFERROR(VLOOKUP(F40, Price_Master!$A$2:$C$201, 2, FALSE), "") -> 12000 | H40: =IFERROR(VLOOKUP(F40, Price_Master!$A$2:$C$201, 3, FALSE), 0) -> 0.05 | I40: =IFERROR(G40*H40, "") -> 600
...

Sheet Test_Count
A3: Test Name | B3: Test Count
A4: CP(A) | B4: 28
A5: Creat | B5: 17
A6: E Lytes | B6: 12
A7: URE | B7: 11
A8: HCV | B8: 10
A9: MP (ICT) | B9: 10
A10: HBsAg | B10: 10
A11: LFT | B11: 10
A12: CRP | B12: 9
A13: HIV | B13: 8
A14: VDRL | B14: 7
A15: Lipid | B15: 7
... A37: Grand Total | B37: 195

Sheet ReferBy-Table
A1: Test Name | B1: (All)
A3: Refer Names | B3: Total Refer Fee Amount
A4: Phy | B4: 167000
A5: NMMN | B5: 111750
A6: MCLH | B6: 46300
A7: Self | B7: 21700
A8: Pyi Kyaw | B8: 14750
A9: BBH | B9: 9050
A10: ANM | B10: 8750
A11: AMH | B11: 7300
A12: Phoe Khin | B12: 4500
A13: Grace | B13: 4500
A14: ဂရုဏာဆေးခန်း | B14: 2600
A15: OG | B15: 600
A16: Grand Total | B16: 398800

Sheet Price_Master
A1: Test | B1: Price | C1: Fee %
A2: CP(A) | B2: 30000 | C2: 0.15
A3: G&M Rh | B3: 10000 | C3: 0.15
A4: ESR | B4: 10000 | C4: 0.15
A5: G&M | B5: 7000 | C5: 0.15
A6: E lytes | B6: 30000 | C6: 0.15
A7: Ur | B7: 10000 | C7: 0.15
A8: Creat | B8: 10000 | C8: 0.15
A9: U/A | B9: 10000 | C9: 0.15
A10: Amy | B10: 10000 | C10: 0.15
A11: Lipid | B11: 36000 | C11: 0.15
A12: TC | B12: 10000 | C12: 0.15
A13: TG | B13: 10000 | C13: 0.15
... A69: Trop-T | B69: 40000 | C69: 0
